package com.dummy.myerp.technical.exception;

import org.junit.Assert;
import org.junit.jupiter.api.Test;


public class FunctionalExceptionUT {
	
	
	@Test
	public void checkFunctionalException() {
		Exception exception = new Exception();
		Throwable pcause = new Throwable();
		exception.initCause(pcause);
		
		Exception functionalException = new FunctionalException(pcause);
		
		
		Assert.assertTrue("Probl√®me dans la reconnaissance de l'exception par FunctionalException", functionalException.getCause().toString().equals(exception.getCause().toString())); 
		
	}

}
